Workbook

Sheet Dashboard
A1: MD MARBLE — FACTORY CONTROL DASHBOARD
A2: MD Finishes • Triq ix-Xwieni, Alberttown, Marsa • VAT MT26862103 • live overview (figures update automatically)
B4: KEY NUMBERS
B5: INVOICED & DELIVERED (incl VAT) | E5: PIPELINE — QUOTES AWAITING CONFIRM
B6: =SUMIF('Orders & Payments'!$G$3:$G$200,"Invoice",'Orders & Payments'!$N$3:$N$200)+SUMIF('Orders & Payments'!$G$3:$G$200,"Delivery-Invoice",'Orders & Payments'!$N$3:$N$200) -> 139259.89 | E6: =SUMIF('Orders & Payments'!$G$3:$G$200,"Quotation",'Orders & Payments'!$N$3:$N$200) -> 286888.31
B8: TOTAL RECEIVED / DEPOSITS | E8: OUTSTANDING TO COLLECT
B9: =SUM('Orders & Payments'!$O$3:$O$200) -> 12372.58 | E9: =SUMIF('Orders & Payments'!$G$3:$G$200,"Invoice",'Orders & Payments'!$P$3:$P$200)+SUMIF('Orders & Payments'!$G$3:$G$200,"Delivery-Invoice",'Orders & Payments'!$P$3:$P$200) -> 126887.31
B11: JOBS / DOCUMENTS LOGGED | E11: QUOTES AWAITING CONFIRMATION
B12: =COUNTA('Orders & Payments'!$A$3:$A$200) -> 86 | E12: =COUNTIF('Orders & Payments'!$G$3:$G$200,"Quotation") -> 35
B15: BY DOCUMENT TYPE | E15: BY WORK TYPE
B16: Type | C16: Count | D16: Value (incl VAT) | E16: Type | F16: Count | G16: Value (incl VAT)
B17: Quotation | C17: =COUNTIF('Orders & Payments'!$G$3:$G$200,"Quotation") -> 35 | D17: =SUMIF('Orders & Payments'!$G$3:$G$200,"Quotation",'Orders & Payments'!$N$3:$N$200) -> 286888.31 | E17: Supply Only | F17: =COUNTIF('Orders & Payments'!$J$3:$J$200,"Supply Only") -> 38 | G17: =SUMIF('Orders & Payments'!$J$3:$J$200,"Supply Only",'Orders & Payments'!$N$3:$N$200) -> 167223.71
B18: Invoice | C18: =COUNTIF('Orders & Payments'!$G$3:$G$200,"Invoice") -> 22 | D18: =SUMIF('Orders & Payments'!$G$3:$G$200,"Invoice",'Orders & Payments'!$N$3:$N$200) -> 49686.05 | E18: Supply & Install | F18: =COUNTIF('Orders & Payments'!$J$3:$J$200,"Supply & Install") -> 42 | G18: =SUMIF('Orders & Payments'!$J$3:$J$200,"Supply & Install",'Orders & Payments'!$N$3:$N$200) -> 244234.29
B19: Delivery-Invoice | C19: =COUNTIF('Orders & Payments'!$G$3:$G$200,"Delivery-Invoice") -> 28 | D19: =SUMIF('Orders & Payments'!$G$3:$G$200,"Delivery-Invoice",'Orders & Payments'!$N$3:$N$200) -> 89573.84 | E19: Service | F19: =COUNTIF('Orders & Payments'!$J$3:$J$200,"Service") -> 6 | G19: =SUMIF('Orders & Payments'!$J$3:$J$200,"Service",'Orders & Payments'!$N$3:$N$200) -> 24690.2
B20: Credit Note | C20: =COUNTIF('Orders & Payments'!$G$3:$G$200,"Credit Note") -> 1 | D20: =SUMIF('Orders & Payments'!$G$3:$G$200,"Credit Note",'Orders & Payments'!$N$3:$N$200) -> 10000
B22: How to use: fill the yellow cells. Everything else (Pending, Dashboard, Client totals) calculates by itself. Tabs are grouped: bronze = overview, blue = sales/orders, green = factory & people.

Sheet Orders & Payments
A1: ORDERS, DELIVERIES & PAYMENTS
A2: Order ID | B2: Date | C2: Client | D2: Site / Location | E2: Description of Works | F2: Material | G2: Doc Type | H2: Quote No. | I2: Invoice No. | J2: Work Type | K2: Confirmed? | L2: Amount excl VAT | M2: VAT | N2: Total incl VAT | O2: Deposit / Paid | P2: Pending | Q2: Payment Due When | R2: Payment Status | S2: Lead Time (days) | T2: Delivery / Install Date | U2: Notes
A3: MD-001 | B3: 45625 | C3: Luqa New Airport | D3: Luqa Airport | E3: Supply & Install of Biege Lime Stone (31.2 sqm) + installation 93 lm, plus extra door sills & leveling labour | F3: Biege Lime Stone | G3: Quotation | H3: 175 | J3: Supply & Install | K3: No | L3: 6603.32 | M3: 1188.6 | N3: 7791.92 | O3: 0 | P3: =N3-O3 -> 7791.92 | Q3: Deposit on Confirmation | R3: Awaiting Confirmation | U3: Old quote (Nov-2024) — confirm if still live or already done. Filename hint: Satariano / Luqa.
A4: MD-002 | B4: 45868 | C4: Qrendi (site) | D4: Qrendi | E4: Supply of marble — limestone 90×60 brushed (10.8 + 2.16 m²), travertine 40×60 unfilled 12 sqm, 240×240 slab | F4: Limestone / Travertine | G4: Quotation | H4: 229 | J4: Supply Only | K4: No | L4: =756+151+340+372 -> 1619 | M4: 291.42 | N4: 1910.42 | O4: 0 | P4: =N4-O4 -> 1910.42 | Q4: Deposit on Confirmation | R4: Awaiting Confirmation | U4: No company name / VAT on doc — confirm client identity.
A5: MD-003 | B5: 45905 | C5: WE MALTA LTD | D5: Pieta | E5: Supply & deliver of Biege stone for lifts — Pieta site | F5: Biege Stone | G5: Invoice | H5: 390 | I5: 400186 | J5: Supply Only | K5: Yes | L5: 1380 | M5: 248.4 | N5: 1628.4 | O5: 0 | P5: =N5-O5 -> 1628.4 | Q5: On Delivery | R5: Pending | U5: VAT 26150532, Birkirkara. Lift cladding supply.
A6: MD-004 | B6: 45917 | C6: Marsa – Hand-Crafted Job | D6: Marsa | E6: Supply & install of hand-crafted marble designs, full bullnose edging & on-site polish | F6: Marble (hand-crafted) | G6: Quotation | H6: 239 | J6: Supply & Install | K6: No | L6: 3770 | M6: 678.6 | N6: 4448.6 | O6: 0 | P6: =N6-O6 -> 4448.6 | Q6: Deposit on Confirmation | R6: Awaiting Confirmation | U6: Doc shows customer: "MARSA" (no VAT). Confirm contact.
A7: MD-005 | B7: 45918 | C7: AX CONSTRUCTION LIMITED | D7: Airport / Mosta | E7: Supply of Biege Limestone | F7: Biege Limestone | G7: Delivery-Invoice | I7: 1000236 | J7: Supply Only | K7: Yes | L7: 225 | M7: 40.5 | N7: 265.5 | O7: 0 | P7: =N7-O7 -> 265.5 | Q7: On Delivery | R7: Pending | U7: VAT 12949330, Triq id-Difiza Civili, Mosta.
A8: MD-006 | B8: 45923 | C8: Amanda | D8: Buggiba | E8: Supply of granite (cut to ~22 sizes) — Buggiba site | F8: Granite | G8: Delivery-Invoice | I8: 1000238 | J8: Supply Only | K8: Yes | L8: 282 | M8: 50.76 | N8: 332.76 | O8: 0 | P8: =N8-O8 -> 332.76 | Q8: On Delivery | R8: Pending | U8: Doc shows "AMANDA" (no VAT). Many cut pieces listed.
A9: MD-007 | B9: 45926 | C9: 1909 INVESTMENTS LTD | D9: Zebbug | E9: CREDIT NOTE against invoice 400190 — Supply & Install Travertine Sills & Stairs | F9: Travertine | G9: Credit Note | H9: 29 | I9: (ref 400190) | J9: Supply & Install | K9: N/A | L9: 8474.58 | M9: 1525.42 | N9: 10000 | O9: 0 | P9: =N9-O9 -> 10000 | Q9: See Notes | R9: Credit Note | U9: Credit note offsets Invoice 400190 (not uploaded). VAT 20541622.
A10: MD-008 | B10: 45926 | C10: 1909 INVESTMENTS LTD | D10: Zebbug | E10: Supply & Install of Travertine Sills & Stairs | F10: Travertine | G10: Invoice | H10: 390 | I10: 400191 | J10: Supply & Install | K10: Yes | L10: 8898.31 | M10: 1601.7 | N10: 10500.01 | O10: 0 | P10: =N10-O10 -> 10500.01 | Q10: On Completion | R10: Pending | U10: VAT 20541622, BG House No.3, Zebbug.
A11: MD-009 | B11: 45929 | C11: SUNSPOTS LTD | D11: Pieta | E11: Supply of Biege Travertine 40×60 + Galala sills & stairs — Pieta site | F11: Travertine & Galala | G11: Invoice | H11: 390 | I11: 400192 | J11: Supply Only | K11: Yes | L11: 3000 | M11: 540 | N11: 3540 | O11: 0 | P11: =N11-O11 -> 3540 | Q11: On Delivery | R11: Pending | U11: VAT 12527802, St Julians.
A12: MD-010 | B12: 45931 | C12: ROGER SATARIANO & SON LTD | D12: Mriehel | E12: Supply & Install of Lava Black marble for stairs & façade (31.6 sqm) — Mriehel site | F12: Lava Black | G12: Quotation | H12: 243 | J12: Supply & Install | K12: No | L12: 4330 | M12: 779.4 | N12: 5109.4 | O12: 0 | P12: =N12-O12 -> 5109.4 | Q12: Deposit on Confirmation | R12: Awaiting Confirmation | U12: VAT 1055-2337, 122 Msida Valley Rd, Birkirkara.
A13: MD-011 | B13: 45936 | C13: ICI LIMITED | D13: Birkirkara | E13: Supply of Travertine incl material + cutting + round edges (9.2 sqm) | F13: Travertine | G13: Invoice | H13: 390 | I13: 400193 | J13: Supply Only | K13: Yes | L13: 690 | M13: 124.2 | N13: 814.2 | O13: 0 | P13: =N13-O13 -> 814.2 | Q13: On Delivery | R13: Pending | U13: VAT MT17813220, Triq l-Artigjanat Zone 4, Birkirkara.
A14: MD-012 | B14: 45959 | C14: ICI LIMITED | D14: Villa Fiorini | E14: Villa Fiorini — remove & replace marble sills + install | F14: Marble (sills) | G14: Quotation | H14: 259 | J14: Supply & Install | K14: No | L14: 480 | M14: 86.4 | N14: 566.4 | O14: 0 | P14: =N14-O14 -> 566.4 | Q14: Deposit on Confirmation | R14: Awaiting Confirmation | U14: Same client as MD-011/MD-018 (ICI Ltd).
A15: MD-013 | B15: 45959 | C15: Jhon Soler | D15: 15 Howard St, Sliema | E15: Supply & Install of 7 lifts cladding + delivery & unloading to each floor | F15: Marble cladding | G15: Quotation | H15: 258 | J15: Supply & Install | K15: No | L15: =2170+150 -> 2320 | M15: 417.6 | N15: 2737.6 | O15: 0 | P15: =N15-O15 -> 2737.6 | Q15: Deposit on Confirmation | R15: Awaiting Confirmation | U15: Doc shows "Jhon Soler", Sliema (no VAT).
A16: MD-014 | B16: 45965 | C16: 1909 INVESTMENTS LTD | D16: Zebbug — Flats 1–12 | E16: Supply & Install of Travertine — covers Flats 1,2,3,4,5,6,7,8,9,10,11 & 12 | F16: Travertine | G16: Delivery-Invoice | I16: 1000252 | J16: Supply & Install | K16: Yes | L16: 5554 | M16: 999.72 | N16: 6553.72 | O16: 0 | P16: =N16-O16 -> 6553.72 | Q16: On Completion | R16: Pending | U16: VAT 20541622. Supply 3,154 + Install 2,400.
A17: MD-015 | B17: 45965 | C17: Robert (RMX Ltd) | D17: Marsa | E17: Supply + delivery of Silvia Marble | F17: Silvia Marble | G17: Delivery-Invoice | I17: 1000253 | J17: Supply Only | K17: Yes | L17: 2300 | M17: 414 | N17: 2714 | O17: 0 | P17: =N17-O17 -> 2714 | Q17: On Delivery | R17: Pending | U17: Doc shows "MARSA"; filename hint: Robert / RMX Ltd. Confirm.
A18: MD-016 | B18: 45965 | C18: ROGER SATARIANO & SON LTD | D18: Mriehel | E18: Supply & Install of Lava aluminium door sills (extra) — Mriehel site | F18: Lava | G18: Delivery-Invoice | I18: 1000254 | J18: Supply & Install | K18: Yes | L18: 265 | M18: 47.7 | N18: 312.7 | O18: 0 | P18: =N18-O18 -> 312.7 | Q18: On Completion | R18: Pending | U18: VAT 1055-2337. Extra to the Mriehel Lava Black job (MD-010).
A19: MD-017 | B19: 45966 | C19: PROJECT TECHNIK LTD | D19: Qormi | E19: Supply of Trista Grey (27 sqm) | F19: Trista Grey | G19: Delivery-Invoice | I19: 1000255 | J19: Supply Only | K19: Yes | L19: 1485 | M19: 267.3 | N19: 1752.3 | O19: 0 | P19: =N19-O19 -> 1752.3 | Q19: On Delivery | R19: Pending | U19: VAT MT19667814, Cannon Road, Qormi.
A20: MD-018 | B20: 45966 | C20: ICI LIMITED | D20: Sliema (Gafar) | E20: Touch up & paint — Gafar at Sliema | F20: Touch-up / paint | G20: Invoice | H20: 390 | I20: 400195 | J20: Service | K20: Yes | L20: 800 | M20: 144 | N20: 944 | O20: 0 | P20: =N20-O20 -> 944 | Q20: See Notes | R20: Pending | U20: Agreed split per doc: €660.80 cash + €283.20 barter (= €944).
A21: MD-019 | B21: 45967 | C21: Lee | D21: Siggiewi / Marsa | E21: Supply of Biege Travertine sills (11 cut sizes) + delivery | F21: Biege Travertine | G21: Delivery-Invoice | I21: 1000256 | J21: Supply Only | K21: Yes | L21: 370 | M21: 66.6 | N21: 436.6 | O21: 0 | P21: =N21-O21 -> 436.6 | Q21: On Delivery | R21: Pending | U21: Doc shows "Lee", Marsa; filename hint: Siggiewi.
A22: MD-020 | B22: 45975 | C22: STEPHEN FARRUGIA | D22: Santa Venera | E22: Supply & Install of Marble — BALANCE on Quote 227 (project total €13,806 incl VAT; deposit €5,522.40 already paid on Inv 400181) | F22: Marble | G22: Delivery-Invoice | H22: 227 | I22: 1000258 | J22: Supply & Install | K22: Yes | L22: 7020 | M22: 1263.6 | N22: 8283.6 | O22: 0 | P22: =N22-O22 -> 8283.6 | Q22: On Completion | R22: Pending | U22: VAT mt13709420. This row = remaining balance €8,283.60. Deposit already collected via Inv 400181. Fiscal Invoice 400196 (14/11/2025) was issued for this same balance — same sale, counted once here.
A23: MD-021 | B23: 45973 | C23: Christian Fenech | D23: Msida | E23: Supply of Biege stone sills (24 lm) | F23: Biege stone | G23: Delivery-Invoice | I23: 1000257 | J23: Supply Only | K23: Yes | L23: 384 | M23: 69.12 | N23: 453.12 | O23: 0 | P23: =N23-O23 -> 453.12 | Q23: On Delivery | R23: Pending | U23: VAT 1690-8714, Msida.
A24: MD-022 | B24: 45976 | C24: Dario | D24: Marsa | E24: Supply of kitchen top — Quartz Gold (OPTION A) | F24: Quartz Gold | G24: Quotation | H24: 264 | J24: Supply Only | K24: No | L24: 3400 | M24: 612 | N24: 4012 | O24: 0 | P24: =N24-O24 -> 4012 | Q24: Deposit on Confirmation | R24: Awaiting Confirmation | U24: OPTION A for Dario kitchen. Alternative to Q265 (Calacatta) — client picks ONE. No VAT on doc.
A25: MD-023 | B25: 45976 | C25: Dario | D25: Marsa | E25: Supply of kitchen top — Quartz Calacatta Gold (OPTION B) | F25: Quartz Calacatta Gold | G25: Quotation | H25: 265 | J25: Supply Only | K25: No | L25: 3025 | M25: 544.5 | N25: 3569.5 | O25: 0 | P25: =N25-O25 -> 3569.5 | Q25: Deposit on Confirmation | R25: Awaiting Confirmation | U25: OPTION B for Dario kitchen. Alternative to Q264 (Quartz Gold) — client picks ONE. No VAT on doc.
A26: MD-024 | B26: 45978 | C26: BURMARRAD GROUP PROPERTIES LIMITED | D26: Marsa | E26: Plastering & painting finishings — clean ceiling, treat & apply Sika, plaster & paint | F26: Plaster / paint | G26: Invoice | I26: 5000140 | J26: Service | K26: Yes | L26: 1500 | M26: 270 | N26: 1770 | O26: 0 | P26: =N26-O26 -> 1770 | Q26: On Completion | R26: Pending | U26: *** Billed under MD FINISHES (VAT MT25476001 / Mohammed Aldeeb), NOT MD Marble. Client VAT MT30717708. Confirm if it belongs in these books.
A27: MD-025 | B27: 45978 | C27: BURMARRAD GROUP PROPERTIES LIMITED | D27: Marsa | E27: Touch up & paint | F27: Paint (touch-up) | G27: Invoice | I27: 5000141 | J27: Service | K27: Yes | L27: 450 | M27: 81 | N27: 531 | O27: 0 | P27: =N27-O27 -> 531 | Q27: On Completion | R27: Pending | U27: *** Billed under MD FINISHES (Mohammed Aldeeb), NOT MD Marble. Same client as MD-024.
A28: MD-026 | B28: 45979 | C28: LAS VEGAS RESORT LTD | D28: Paceville (pool) | E28: Supply of 3cm Hammered Marble — extra pieces for the pool (ordered by Emmanuel) | F28: Hammered Marble 3cm | G28: Delivery-Invoice | I28: 1000259 | J28: Supply Only | K28: Yes | L28: 847.5 | M28: 152.55 | N28: 1000.05 | O28: 0 | P28: =N28-O28 -> 1000.05 | Q28: On Delivery | R28: Pending | U28: VAT MT28194902, Dragonara Rd, Paceville.
A29: MD-027 | B29: 45989 | C29: SUNSPOTS LTD | D29: Pieta | E29: Supply of Galala Marble for Lifts + Extras (ordered by Ezzideen) | F29: Galala | G29: Invoice | H29: 263 | I29: 400198 | J29: Supply Only | K29: Yes | L29: 2700 | M29: 486 | N29: 3186 | O29: 0 | P29: =N29-O29 -> 3186 | Q29: On Delivery | R29: Pending | U29: Same job across 3 docs (counted once): quoted as Q263 to contact "Albert" (Pieta) -> delivered via DN 1000260 -> fiscal Inv 400198. Gross 3,000 less 300 discount = 2,700 net.
A30: MD-028 | B30: 45992 | C30: ROGER SATARIANO & SON LTD | D30: Pool & BBQ area | E30: Supply & Install of Travertine for the pool & barbeque area | F30: Travertine | G30: Quotation | H30: 267 | J30: Supply & Install | K30: No | L30: 3780 | M30: 680.4 | N30: 4460.4 | O30: 0 | P30: =N30-O30 -> 4460.4 | Q30: Deposit on Confirmation | R30: Awaiting Confirmation | U30: VAT 1055-2337. New job, separate from the Mriehel Lava work (MD-010/MD-016).
A31: MD-029 | B31: 46007 | C31: JAA CO LTD | D31: Swieqi | E31: Supply of Crema Marfil — extra sills, 6 cut sizes (ordered by Ronaldo) | F31: Crema Marfil | G31: Invoice | H31: 268 | I31: 400205 | J31: Supply Only | K31: Yes | L31: 415 | M31: 74.7 | N31: 489.7 | O31: 0 | P31: =N31-O31 -> 489.7 | Q31: On Delivery | R31: Pending | U31: Quote 268 was confirmed & invoiced as Inv 400205 (16/12/2025). VAT MT2630-3713, Arzella, Swieqi.
A32: MD-030 | B32: 46067 | C32: WE MALTA LTD | D32: Attard | E32: Supply & Install of Biege Atone Marble — stairs (73.25 sqm) & skirting (64.40 lm), Ha Attard site | F32: Biege Atone | G32: Delivery-Invoice | H32: 272 | I32: 1000294 | J32: Supply & Install | K32: Yes | L32: 8030.55 | M32: 1445.5 | N32: 9476.05 | O32: 4245.17 | P32: =N32-O32 -> 5230.88 | Q32: On Completion | R32: Partial | U32: Quote 272 (orig €10,612.92) CONFIRMED & realised as Delivery-Invoice 1000294 (14/02/2026). Terms 40/30/30. 40% deposit €4,245.17 stated on doc (CONFIRM received); balance €5,230.88. VAT 26150532.
A33: MD-031 | B33: 45996 | C33: Purchase Order 1 (MARSA) | D33: Marsa (TBC) | E33: Supply & Install of Crema Galala — stairs, landing & entrance (65.6 sqm) + skirting | F33: Crema Galala | G33: Quotation | H33: 271 | J33: Supply & Install | K33: No | L33: 6935.8 | M33: 1248.44 | N33: 8184.24 | O33: 0 | P33: =N33-O33 -> 8184.24 | Q33: Deposit on Confirmation | R33: Awaiting Confirmation | U33: Doc customer literally "PURCHASE ORDER 1" (Marsa, no VAT) — identify the real client.
A34: MD-032 | B34: 46067 | C34: WE MALTA LTD | D34: Birkirkara | E34: Supply & Install of Biege Atone Marble — internal stairs (51.26 sqm) & internal skirting (62 lm), Birkirkara site | F34: Biege Atone | G34: Delivery-Invoice | H34: 273 | I34: 1000295 | J34: Supply & Install | K34: Yes | L34: 6231.5 | M34: 1121.67 | N34: 7353.17 | O34: 3364.7 | P34: =N34-O34 -> 3988.47 | Q34: On Completion | R34: Partial | U34: Quote 273 (orig €10,105.99) CONFIRMED & realised as Delivery-Invoice 1000295 (14/02/2026). 40% deposit €3,364.70 stated (CONFIRM received); doc states 60% balance €3,955.47 (deposit+balance = €7,320.17 vs total €7,353.17 — €33 rounding diff on doc). VAT 26150532.
A35: MD-033 | B35: 45999 | C35: Purchase Order 1 (MARSA) | D35: Penthouse (TBC) | E35: Supply & Install of Travertine Noce — penthouse (8.6 sqm) | F35: Travertine Noce | G35: Quotation | H35: 274 | J35: Supply & Install | K35: No | L35: 1088 | M35: 195.84 | N35: 1283.84 | O35: 0 | P35: =N35-O35 -> 1283.84 | Q35: Deposit on Confirmation | R35: Awaiting Confirmation | U35: Doc customer "PURCHASE ORDER 1" (Marsa, no VAT) — identify the real client.
A36: MD-034 | B36: 45999 | C36: UDRI INVESTMENTS LTD | D36: Attard | E36: Supply & Install of Bianco Marble — Attard site | F36: Bianco Marble | G36: Delivery-Invoice | I36: 1000265 | J36: Supply & Install | K36: Yes | L36: 1003.33 | M36: 180.6 | N36: 1183.93 | O36: 0 | P36: =N36-O36 -> 1183.93 | Q36: On Completion | R36: Pending | U36: VAT MT23109635, Msida Park, Msida.
A37: MD-035 | B37: 45999 | C37: UNITED INVESTMENT HOLDINGS LTD | D37: Attard | E37: Supply & Install of Bianco Marble — Attard site | F37: Bianco Marble | G37: Delivery-Invoice | I37: 1000266 | J37: Supply & Install | K37: Yes | L37: 2006.67 | M37: 361.2 | N37: 2367.87 | O37: 0 | P37: =N37-O37 -> 2367.87 | Q37: On Completion | R37: Pending | U37: VAT shows 00000 — confirm. 4 Timber Wharf, Marsa. Same Attard / Bianco job as UDRI (MD-034) — possibly linked.
A38: MD-036 | B38: 46000 | C38: ICI LIMITED | D38: Tal-Mandra (Villa 10) | E38: Supply & Install of Travertine & Bianco Marble — Villa 10 (internal entrance, sill, internal marble) | F38: Travertine & Bianco | G38: Invoice | I38: 400200 | J38: Supply & Install | K38: Yes | L38: 941 | M38: 169.38 | N38: 1110.38 | O38: 0 | P38: =N38-O38 -> 1110.38 | Q38: See Notes | R38: Pending | U38: VAT MT17813220. Payment split per doc: 80% cash €888.30 + 20% barter €222.08.
A39: MD-037 | B39: 46000 | C39: ICI LIMITED | D39: Tal-Mandra (Villa 11) | E39: Supply & Install of Travertine & Bianco Marble — Villa 11 (internal & external sills) | F39: Travertine & Bianco | G39: Invoice | I39: 400201 | J39: Supply & Install | K39: Yes | L39: 928 | M39: 167.04 | N39: 1095.04 | O39: 0 | P39: =N39-O39 -> 1095.04 | Q39: See Notes | R39: Pending | U39: VAT MT17813220. Payment split per doc: 80% cash €876.04 + 20% barter €219.
A40: MD-038 | B40: 45961 | C40: ICI LIMITED | D40: ICI site | E40: Supply of Travertine — material + cutting + round edges | F40: Travertine | G40: Invoice | I40: 400212 | J40: Supply Only | K40: Yes | L40: 845 | M40: 152.1 | N40: 997.1 | O40: 0 | P40: =N40-O40 -> 997.1 | Q40: On Delivery | R40: Pending | U40: VAT MT17813220. Older invoice (Oct-2025), added later.
...

Sheet Client Directory
A1: CLIENT DIRECTORY
A2: Client ID | B2: Client Name | C2: VAT No. | D2: Location / Address | E2: Contact (phone / email) | F2: Client Type | G2: First Job | H2: # Docs | I2: Total Quoted | J2: Total Invoiced | K2: Received | L2: Outstanding | M2: Materials / Notes
A3: C-001 | B3: WE MALTA LTD | C3: 26150532 | D3: Isabella Court Flt, Triq il-Mejjiesa, Birkirkara | F3: Developer / Contractor | G3: 45905 | H3: =COUNTIF('Orders & Payments'!$C$3:$C$200,$B3) -> 4 | I3: =SUMIFS('Orders & Payments'!$N$3:$N$200,'Orders & Payments'!$C$3:$C$200,$B3,'Orders & Payments'!$G$3:$G$200,"Quotation") -> 0 | J3: =SUMIFS('Orders & Payments'!$N$3:$N$200,'Orders & Payments'!$C$3:$C$200,$B3,'Orders & Payments'!$G$3:$G$200,"Invoice")+SUMIFS('Orders & Payments'!$N$3:$N$200,'Orders & Payments'!$C$3:$C$200,$B3,'Orders & Payments'!$G$3:$G$200,"Delivery-Invoice") -> 20321.43 | K3: =SUMIFS('Orders & Payments'!$O$3:$O$200,'Orders & Payments'!$C$3:$C$200,$B3) -> 7609.87 | L3: =SUMIFS('Orders & Payments'!$P$3:$P$200,'Orders & Payments'!$C$3:$C$200,$B3,'Orders & Payments'!$G$3:$G$200,"Invoice")+SUMIFS('Orders & Payments'!$P$3:$P$200,'Orders & Payments'!$C$3:$C$200,$B3,'Orders & Payments'!$G$3:$G$200,"Delivery-Invoice") -> 12711.56 | M3: Biege stone lift cladding (Pieta).
A4: C-002 | B4: AX CONSTRUCTION LIMITED | C4: 12949330 | D4: Triq id-Difiza Civili, Mosta MST1741 | F4: Construction Co. | G4: 45918 | H4: =COUNTIF('Orders & Payments'!$C$3:$C$200,$B4) -> 1 | I4: =SUMIFS('Orders & Payments'!$N$3:$N$200,'Orders & Payments'!$C$3:$C$200,$B4,'Orders & Payments'!$G$3:$G$200,"Quotation") -> 0 | J4: =SUMIFS('Orders & Payments'!$N$3:$N$200,'Orders & Payments'!$C$3:$C$200,$B4,'Orders & Payments'!$G$3:$G$200,"Invoice")+SUMIFS('Orders & Payments'!$N$3:$N$200,'Orders & Payments'!$C$3:$C$200,$B4,'Orders & Payments'!$G$3:$G$200,"Delivery-Invoice") -> 265.5 | K4: =SUMIFS('Orders & Payments'!$O$3:$O$200,'Orders & Payments'!$C$3:$C$200,$B4) -> 0 | L4: =SUMIFS('Orders & Payments'!$P$3:$P$200,'Orders & Payments'!$C$3:$C$200,$B4,'Orders & Payments'!$G$3:$G$200,"Invoice")+SUMIFS('Orders & Payments'!$P$3:$P$200,'Orders & Payments'!$C$3:$C$200,$B4,'Orders & Payments'!$G$3:$G$200,"Delivery-Invoice") -> 265.5 | M4: Biege limestone (Airport).
A5: C-003 | B5: 1909 INVESTMENTS LTD | C5: 20541622 | D5: BG House No.3, Triq Guliernu Lorenzi, Zebbug | F5: Developer | G5: 45926 | H5: =COUNTIF('Orders & Payments'!$C$3:$C$200,$B5) -> 4 | I5: =SUMIFS('Orders & Payments'!$N$3:$N$200,'Orders & Payments'!$C$3:$C$200,$B5,'Orders & Payments'!$G$3:$G$200,"Quotation") -> 33367.57 | J5: =SUMIFS('Orders & Payments'!$N$3:$N$200,'Orders & Payments'!$C$3:$C$200,$B5,'Orders & Payments'!$G$3:$G$200,"Invoice")+SUMIFS('Orders & Payments'!$N$3:$N$200,'Orders & Payments'!$C$3:$C$200,$B5,'Orders & Payments'!$G$3:$G$200,"Delivery-Invoice") -> 17053.73 | K5: =SUMIFS('Orders & Payments'!$O$3:$O$200,'Orders & Payments'!$C$3:$C$200,$B5) -> 0 | L5: =SUMIFS('Orders & Payments'!$P$3:$P$200,'Orders & Payments'!$C$3:$C$200,$B5,'Orders & Payments'!$G$3:$G$200,"Invoice")+SUMIFS('Orders & Payments'!$P$3:$P$200,'Orders & Payments'!$C$3:$C$200,$B5,'Orders & Payments'!$G$3:$G$200,"Delivery-Invoice") -> 17053.73 | M5: Travertine sills & stairs across 12 flats. Incl. 1 credit note (vs Inv 400190).
A6: C-004 | B6: SUNSPOTS LTD | C6: 12527802 | D6: St Julians | F6: Developer / Contractor | G6: 45929 | H6: =COUNTIF('Orders & Payments'!$C$3:$C$200,$B6) -> 2 | I6: =SUMIFS('Orders & Payments'!$N$3:$N$200,'Orders & Payments'!$C$3:$C$200,$B6,'Orders & Payments'!$G$3:$G$200,"Quotation") -> 0 | J6: =SUMIFS('Orders & Payments'!$N$3:$N$200,'Orders & Payments'!$C$3:$C$200,$B6,'Orders & Payments'!$G$3:$G$200,"Invoice")+SUMIFS('Orders & Payments'!$N$3:$N$200,'Orders & Payments'!$C$3:$C$200,$B6,'Orders & Payments'!$G$3:$G$200,"Delivery-Invoice") -> 6726 | K6: =SUMIFS('Orders & Payments'!$O$3:$O$200,'Orders & Payments'!$C$3:$C$200,$B6) -> 0 | L6: =SUMIFS('Orders & Payments'!$P$3:$P$200,'Orders & Payments'!$C$3:$C$200,$B6,'Orders & Payments'!$G$3:$G$200,"Invoice")+SUMIFS('Orders & Payments'!$P$3:$P$200,'Orders & Payments'!$C$3:$C$200,$B6,'Orders & Payments'!$G$3:$G$200,"Delivery-Invoice") -> 6726 | M6: Travertine + Galala sills & stairs (Pieta).
A7: C-005 | B7: ROGER SATARIANO & SON LTD | C7: 1055-2337 | D7: 122 Msida Valley Road, Birkirkara | F7: Contractor | G7: 45931 | H7: =COUNTIF('Orders & Payments'!$C$3:$C$200,$B7) -> 4 | I7: =SUMIFS('Orders & Payments'!$N$3:$N$200,'Orders & Payments'!$C$3:$C$200,$B7,'Orders & Payments'!$G$3:$G$200,"Quotation") -> 9569.8 | J7: =SUMIFS('Orders & Payments'!$N$3:$N$200,'Orders & Payments'!$C$3:$C$200,$B7,'Orders & Payments'!$G$3:$G$200,"Invoice")+SUMIFS('Orders & Payments'!$N$3:$N$200,'Orders & Payments'!$C$3:$C$200,$B7,'Orders & Payments'!$G$3:$G$200,"Delivery-Invoice") -> 1271.45 | K7: =SUMIFS('Orders & Payments'!$O$3:$O$200,'Orders & Payments'!$C$3:$C$200,$B7) -> 0 | L7: =SUMIFS('Orders & Payments'!$P$3:$P$200,'Orders & Payments'!$C$3:$C$200,$B7,'Orders & Payments'!$G$3:$G$200,"Invoice")+SUMIFS('Orders & Payments'!$P$3:$P$200,'Orders & Payments'!$C$3:$C$200,$B7,'Orders & Payments'!$G$3:$G$200,"Delivery-Invoice") -> 1271.45 | M7: Lava Black stairs & façade + extra Lava door sills (Mriehel).
A8: C-006 | B8: ICI LIMITED | C8: MT17813220 | D8: Triq l-Artigjanat Zone 4, Birkirkara Centre | F8: Contractor | G8: 45936 | H8: =COUNTIF('Orders & Payments'!$C$3:$C$200,$B8) -> 17 | I8: =SUMIFS('Orders & Payments'!$N$3:$N$200,'Orders & Payments'!$C$3:$C$200,$B8,'Orders & Payments'!$G$3:$G$200,"Quotation") -> 45937.7 | J8: =SUMIFS('Orders & Payments'!$N$3:$N$200,'Orders & Payments'!$C$3:$C$200,$B8,'Orders & Payments'!$G$3:$G$200,"Invoice")+SUMIFS('Orders & Payments'!$N$3:$N$200,'Orders & Payments'!$C$3:$C$200,$B8,'Orders & Payments'!$G$3:$G$200,"Delivery-Invoice") -> 16292.84 | K8: =SUMIFS('Orders & Payments'!$O$3:$O$200,'Orders & Payments'!$C$3:$C$200,$B8) -> 0 | L8: =SUMIFS('Orders & Payments'!$P$3:$P$200,'Orders & Payments'!$C$3:$C$200,$B8,'Orders & Payments'!$G$3:$G$200,"Invoice")+SUMIFS('Orders & Payments'!$P$3:$P$200,'Orders & Payments'!$C$3:$C$200,$B8,'Orders & Payments'!$G$3:$G$200,"Delivery-Invoice") -> 16292.84 | M8: Travertine supply; Villa Fiorini sill replacement; touch-up & paint (Sliema).
A9: C-007 | B9: PROJECT TECHNIK LTD | C9: MT19667814 | D9: Cannon Road, Qormi QRM9032 | F9: Contractor | G9: 45966 | H9: =COUNTIF('Orders & Payments'!$C$3:$C$200,$B9) -> 4 | I9: =SUMIFS('Orders & Payments'!$N$3:$N$200,'Orders & Payments'!$C$3:$C$200,$B9,'Orders & Payments'!$G$3:$G$200,"Quotation") -> 7599.2 | J9: =SUMIFS('Orders & Payments'!$N$3:$N$200,'Orders & Payments'!$C$3:$C$200,$B9,'Orders & Payments'!$G$3:$G$200,"Invoice")+SUMIFS('Orders & Payments'!$N$3:$N$200,'Orders & Payments'!$C$3:$C$200,$B9,'Orders & Payments'!$G$3:$G$200,"Delivery-Invoice") -> 1752.3 | K9: =SUMIFS('Orders & Payments'!$O$3:$O$200,'Orders & Payments'!$C$3:$C$200,$B9) -> 0 | L9: =SUMIFS('Orders & Payments'!$P$3:$P$200,'Orders & Payments'!$C$3:$C$200,$B9,'Orders & Payments'!$G$3:$G$200,"Invoice")+SUMIFS('Orders & Payments'!$P$3:$P$200,'Orders & Payments'!$C$3:$C$200,$B9,'Orders & Payments'!$G$3:$G$200,"Delivery-Invoice") -> 1752.3 | M9: Trista Grey supply.
A10: C-008 | B10: STEPHEN FARRUGIA | C10: mt13709420 | D10: 59 The Orchids, Triq is-Soll, Santa Venera | F10: Private | G10: 45975 | H10: =COUNTIF('Orders & Payments'!$C$3:$C$200,$B10) -> 1 | I10: =SUMIFS('Orders & Payments'!$N$3:$N$200,'Orders & Payments'!$C$3:$C$200,$B10,'Orders & Payments'!$G$3:$G$200,"Quotation") -> 0 | J10: =SUMIFS('Orders & Payments'!$N$3:$N$200,'Orders & Payments'!$C$3:$C$200,$B10,'Orders & Payments'!$G$3:$G$200,"Invoice")+SUMIFS('Orders & Payments'!$N$3:$N$200,'Orders & Payments'!$C$3:$C$200,$B10,'Orders & Payments'!$G$3:$G$200,"Delivery-Invoice") -> 8283.6 | K10: =SUMIFS('Orders & Payments'!$O$3:$O$200,'Orders & Payments'!$C$3:$C$200,$B10) -> 0 | L10: =SUMIFS('Orders & Payments'!$P$3:$P$200,'Orders & Payments'!$C$3:$C$200,$B10,'Orders & Payments'!$G$3:$G$200,"Invoice")+SUMIFS('Orders & Payments'!$P$3:$P$200,'Orders & Payments'!$C$3:$C$200,$B10,'Orders & Payments'!$G$3:$G$200,"Delivery-Invoice") -> 8283.6 | M10: Marble supply & install. Project €13,806; balance €8,283.60 outstanding (deposit paid).
A11: C-009 | B11: Luqa New Airport | C11: — (confirm) | D11: Luqa Airport project | F11: Project / Site | G11: 45625 | H11: =COUNTIF('Orders & Payments'!$C$3:$C$200,$B11) -> 1 | I11: =SUMIFS('Orders & Payments'!$N$3:$N$200,'Orders & Payments'!$C$3:$C$200,$B11,'Orders & Payments'!$G$3:$G$200,"Quotation") -> 7791.92 | J11: =SUMIFS('Orders & Payments'!$N$3:$N$200,'Orders & Payments'!$C$3:$C$200,$B11,'Orders & Payments'!$G$3:$G$200,"Invoice")+SUMIFS('Orders & Payments'!$N$3:$N$200,'Orders & Payments'!$C$3:$C$200,$B11,'Orders & Payments'!$G$3:$G$200,"Delivery-Invoice") -> 0 | K11: =SUMIFS('Orders & Payments'!$O$3:$O$200,'Orders & Payments'!$C$3:$C$200,$B11) -> 0 | L11: =SUMIFS('Orders & Payments'!$P$3:$P$200,'Orders & Payments'!$C$3:$C$200,$B11,'Orders & Payments'!$G$3:$G$200,"Invoice")+SUMIFS('Orders & Payments'!$P$3:$P$200,'Orders & Payments'!$C$3:$C$200,$B11,'Orders & Payments'!$G$3:$G$200,"Delivery-Invoice") -> 0 | M11: Biege lime stone supply & install — old quote, confirm status.
A12: C-010 | B12: Qrendi (site) | C12: — (confirm) | D12: Qrendi | F12: Project / Site | G12: 45868 | H12: =COUNTIF('Orders & Payments'!$C$3:$C$200,$B12) -> 1 | I12: =SUMIFS('Orders & Payments'!$N$3:$N$200,'Orders & Payments'!$C$3:$C$200,$B12,'Orders & Payments'!$G$3:$G$200,"Quotation") -> 1910.42 | J12: =SUMIFS('Orders & Payments'!$N$3:$N$200,'Orders & Payments'!$C$3:$C$200,$B12,'Orders & Payments'!$G$3:$G$200,"Invoice")+SUMIFS('Orders & Payments'!$N$3:$N$200,'Orders & Payments'!$C$3:$C$200,$B12,'Orders & Payments'!$G$3:$G$200,"Delivery-Invoice") -> 0 | K12: =SUMIFS('Orders & Payments'!$O$3:$O$200,'Orders & Payments'!$C$3:$C$200,$B12) -> 0 | L12: =SUMIFS('Orders & Payments'!$P$3:$P$200,'Orders & Payments'!$C$3:$C$200,$B12,'Orders & Payments'!$G$3:$G$200,"Invoice")+SUMIFS('Orders & Payments'!$P$3:$P$200,'Orders & Payments'!$C$3:$C$200,$B12,'Orders & Payments'!$G$3:$G$200,"Delivery-Invoice") -> 0 | M12: Marble slab supply quote — confirm client name & VAT.
A13: C-011 | B13: Marsa – Hand-Crafted Job | C13: — (confirm) | D13: Marsa | F13: Private / TBC | G13: 45917 | H13: =COUNTIF('Orders & Payments'!$C$3:$C$200,$B13) -> 1 | I13: =SUMIFS('Orders & Payments'!$N$3:$N$200,'Orders & Payments'!$C$3:$C$200,$B13,'Orders & Payments'!$G$3:$G$200,"Quotation") -> 4448.6 | J13: =SUMIFS('Orders & Payments'!$N$3:$N$200,'Orders & Payments'!$C$3:$C$200,$B13,'Orders & Payments'!$G$3:$G$200,"Invoice")+SUMIFS('Orders & Payments'!$N$3:$N$200,'Orders & Payments'!$C$3:$C$200,$B13,'Orders & Payments'!$G$3:$G$200,"Delivery-Invoice") -> 0 | K13: =SUMIFS('Orders & Payments'!$O$3:$O$200,'Orders & Payments'!$C$3:$C$200,$B13) -> 0 | L13: =SUMIFS('Orders & Payments'!$P$3:$P$200,'Orders & Payments'!$C$3:$C$200,$B13,'Orders & Payments'!$G$3:$G$200,"Invoice")+SUMIFS('Orders & Payments'!$P$3:$P$200,'Orders & Payments'!$C$3:$C$200,$B13,'Orders & Payments'!$G$3:$G$200,"Delivery-Invoice") -> 0 | M13: Hand-crafted marble designs quote (doc labelled "MARSA").
A14: C-012 | B14: Robert (RMX Ltd) | C14: — (confirm) | D14: Marsa | F14: TBC | G14: 45965 | H14: =COUNTIF('Orders & Payments'!$C$3:$C$200,$B14) -> 4 | I14: =SUMIFS('Orders & Payments'!$N$3:$N$200,'Orders & Payments'!$C$3:$C$200,$B14,'Orders & Payments'!$G$3:$G$200,"Quotation") -> 0 | J14: =SUMIFS('Orders & Payments'!$N$3:$N$200,'Orders & Payments'!$C$3:$C$200,$B14,'Orders & Payments'!$G$3:$G$200,"Invoice")+SUMIFS('Orders & Payments'!$N$3:$N$200,'Orders & Payments'!$C$3:$C$200,$B14,'Orders & Payments'!$G$3:$G$200,"Delivery-Invoice") -> 12338.08 | K14: =SUMIFS('Orders & Payments'!$O$3:$O$200,'Orders & Payments'!$C$3:$C$200,$B14) -> 0 | L14: =SUMIFS('Orders & Payments'!$P$3:$P$200,'Orders & Payments'!$C$3:$C$200,$B14,'Orders & Payments'!$G$3:$G$200,"Invoice")+SUMIFS('Orders & Payments'!$P$3:$P$200,'Orders & Payments'!$C$3:$C$200,$B14,'Orders & Payments'!$G$3:$G$200,"Delivery-Invoice") -> 12338.08 | M14: Silvia marble supply (doc labelled "MARSA"; filename: Robert/RMX).
... A39: C-037 | B39: Naxxar (site) | C39: — (confirm) | D39: Naxxar | F39: Project / Site (TBC) | G39: 46063 | H39: =COUNTIF('Orders & Payments'!$C$3:$C$200,$B39) -> 1 | I39: =SUMIFS('Orders & Payments'!$N$3:$N$200,'Orders & Payments'!$C$3:$C$200,$B39,'Orders & Payments'!$G$3:$G$200,"Quotation") -> 0 | J39: =SUMIFS('Orders & Payments'!$N$3:$N$200,'Orders & Payments'!$C$3:$C$200,$B39,'Orders & Payments'!$G$3:$G$200,"Invoice")+SUMIFS('Orders & Payments'!$N$3:$N$200,'Orders & Payments'!$C$3:$C$200,$B39,'Orders & Payments'!$G$3:$G$200,"Delivery-Invoice") -> 424.8 | K39: =SUMIFS('Orders & Payments'!$O$3:$O$200,'Orders & Payments'!$C$3:$C$200,$B39) -> 0 | L39: =SUMIFS('Orders & Payments'!$P$3:$P$200,'Orders & Payments'!$C$3:$C$200,$B39,'Orders & Payments'!$G$3:$G$200,"Invoice")+SUMIFS('Orders & Payments'!$P$3:$P$200,'Orders & Payments'!$C$3:$C$200,$B39,'Orders & Payments'!$G$3:$G$200,"Delivery-Invoice") -> 424.8 | M39: Small supply & install (Inv 1000289). Doc on "Purchase Order 1" template — identify client.
A40: C-038 | B40: MSIDA | C40: — (confirm) | D40: Msida | F40: Private / TBC | G40: 46067 | H40: =COUNTIF('Orders & Payments'!$C$3:$C$200,$B40) | I40: =SUMIFS('Orders & Payments'!$N$3:$N$200,'Orders & Payments'!$C$3:$C$200,$B40,'Orders & Payments'!$G$3:$G$200,"Quotation") | J40: =SUMIFS('Orders & Payments'!$N$3:$N$200,'Orders & Payments'!$C$3:$C$200,$B40,'Orders & Payments'!$G$3:$G$200,"Invoice")+SUMIFS('Orders & Payments'!$N$3:$N$200,'Orders & Payments'!$C$3:$C$200,$B40,'Orders & Payments'!$G$3:$G$200,"Delivery-Invoice") | K40: =SUMIFS('Orders & Payments'!$O$3:$O$200,'Orders & Payments'!$C$3:$C$200,$B40) | L40: =SUMIFS('Orders & Payments'!$P$3:$P$200,'Orders & Payments'!$C$3:$C$200,$B40,'Orders & Payments'!$G$3:$G$200,"Invoice")+SUMIFS('Orders & Payments'!$P$3:$P$200,'Orders & Payments'!$C$3:$C$200,$B40,'Orders & Payments'!$G$3:$G$200,"Delivery-Invoice")
A41: C-039 | B41: GUDJA | C41: — (confirm) | D41: Gudja | F41: Private / TBC | G41: 46067 | H41: =COUNTIF('Orders & Payments'!$C$3:$C$200,$B41) | I41: =SUMIFS('Orders & Payments'!$N$3:$N$200,'Orders & Payments'!$C$3:$C$200,$B41,'Orders & Payments'!$G$3:$G$200,"Quotation") | J41: =SUMIFS('Orders & Payments'!$N$3:$N$200,'Orders & Payments'!$C$3:$C$200,$B41,'Orders & Payments'!$G$3:$G$200,"Invoice")+SUMIFS('Orders & Payments'!$N$3:$N$200,'Orders & Payments'!$C$3:$C$200,$B41,'Orders & Payments'!$G$3:$G$200,"Delivery-Invoice") | K41: =SUMIFS('Orders & Payments'!$O$3:$O$200,'Orders & Payments'!$C$3:$C$200,$B41) | L41: =SUMIFS('Orders & Payments'!$P$3:$P$200,'Orders & Payments'!$C$3:$C$200,$B41,'Orders & Payments'!$G$3:$G$200,"Invoice")+SUMIFS('Orders & Payments'!$P$3:$P$200,'Orders & Payments'!$C$3:$C$200,$B41,'Orders & Payments'!$G$3:$G$200,"Delivery-Invoice")
A42: C-040 | B42: Cassar Ship Repair Ltd | C42: MT11461431 | D42: Slip No 6 Cross Road, Marsa | F42: Contractor | G42: 46070 | H42: =COUNTIF('Orders & Payments'!$C$3:$C$200,$B42) | I42: =SUMIFS('Orders & Payments'!$N$3:$N$200,'Orders & Payments'!$C$3:$C$200,$B42,'Orders & Payments'!$G$3:$G$200,"Quotation") | J42: =SUMIFS('Orders & Payments'!$N$3:$N$200,'Orders & Payments'!$C$3:$C$200,$B42,'Orders & Payments'!$G$3:$G$200,"Invoice")+SUMIFS('Orders & Payments'!$N$3:$N$200,'Orders & Payments'!$C$3:$C$200,$B42,'Orders & Payments'!$G$3:$G$200,"Delivery-Invoice") | K42: =SUMIFS('Orders & Payments'!$O$3:$O$200,'Orders & Payments'!$C$3:$C$200,$B42) | L42: =SUMIFS('Orders & Payments'!$P$3:$P$200,'Orders & Payments'!$C$3:$C$200,$B42,'Orders & Payments'!$G$3:$G$200,"Invoice")+SUMIFS('Orders & Payments'!$P$3:$P$200,'Orders & Payments'!$C$3:$C$200,$B42,'Orders & Payments'!$G$3:$G$200,"Delivery-Invoice")
A43: C-041 | B43: Malta International Airport PLC | C43: — (confirm) | D43: Luqa LQA 4000 | F43: Corporate / Airport | G43: 46071 | H43: =COUNTIF('Orders & Payments'!$C$3:$C$200,$B43) | I43: =SUMIFS('Orders & Payments'!$N$3:$N$200,'Orders & Payments'!$C$3:$C$200,$B43,'Orders & Payments'!$G$3:$G$200,"Quotation") | J43: =SUMIFS('Orders & Payments'!$N$3:$N$200,'Orders & Payments'!$C$3:$C$200,$B43,'Orders & Payments'!$G$3:$G$200,"Invoice")+SUMIFS('Orders & Payments'!$N$3:$N$200,'Orders & Payments'!$C$3:$C$200,$B43,'Orders & Payments'!$G$3:$G$200,"Delivery-Invoice") | K43: =SUMIFS('Orders & Payments'!$O$3:$O$200,'Orders & Payments'!$C$3:$C$200,$B43) | L43: =SUMIFS('Orders & Payments'!$P$3:$P$200,'Orders & Payments'!$C$3:$C$200,$B43,'Orders & Payments'!$G$3:$G$200,"Invoice")+SUMIFS('Orders & Payments'!$P$3:$P$200,'Orders & Payments'!$C$3:$C$200,$B43,'Orders & Payments'!$G$3:$G$200,"Delivery-Invoice")
A44: C-042 | B44: Stalagmite Connections | C44: 18130814 | D44: Mqabba | F44: Contractor | G44: 46074 | H44: =COUNTIF('Orders & Payments'!$C$3:$C$200,$B44) | I44: =SUMIFS('Orders & Payments'!$N$3:$N$200,'Orders & Payments'!$C$3:$C$200,$B44,'Orders & Payments'!$G$3:$G$200,"Quotation") | J44: =SUMIFS('Orders & Payments'!$N$3:$N$200,'Orders & Payments'!$C$3:$C$200,$B44,'Orders & Payments'!$G$3:$G$200,"Invoice")+SUMIFS('Orders & Payments'!$N$3:$N$200,'Orders & Payments'!$C$3:$C$200,$B44,'Orders & Payments'!$G$3:$G$200,"Delivery-Invoice") | K44: =SUMIFS('Orders & Payments'!$O$3:$O$200,'Orders & Payments'!$C$3:$C$200,$B44) | L44: =SUMIFS('Orders & Payments'!$P$3:$P$200,'Orders & Payments'!$C$3:$C$200,$B44,'Orders & Payments'!$G$3:$G$200,"Invoice")+SUMIFS('Orders & Payments'!$P$3:$P$200,'Orders & Payments'!$C$3:$C$200,$B44,'Orders & Payments'!$G$3:$G$200,"Delivery-Invoice")
A45: C-043 | B45: Blane | C45: — (confirm) | D45: Santa Lucia | F45: Private / TBC | G45: 46074 | H45: =COUNTIF('Orders & Payments'!$C$3:$C$200,$B45) | I45: =SUMIFS('Orders & Payments'!$N$3:$N$200,'Orders & Payments'!$C$3:$C$200,$B45,'Orders & Payments'!$G$3:$G$200,"Quotation") | J45: =SUMIFS('Orders & Payments'!$N$3:$N$200,'Orders & Payments'!$C$3:$C$200,$B45,'Orders & Payments'!$G$3:$G$200,"Invoice")+SUMIFS('Orders & Payments'!$N$3:$N$200,'Orders & Payments'!$C$3:$C$200,$B45,'Orders & Payments'!$G$3:$G$200,"Delivery-Invoice") | K45: =SUMIFS('Orders & Payments'!$O$3:$O$200,'Orders & Payments'!$C$3:$C$200,$B45) | L45: =SUMIFS('Orders & Payments'!$P$3:$P$200,'Orders & Payments'!$C$3:$C$200,$B45,'Orders & Payments'!$G$3:$G$200,"Invoice")+SUMIFS('Orders & Payments'!$P$3:$P$200,'Orders & Payments'!$C$3:$C$200,$B45,'Orders & Payments'!$G$3:$G$200,"Delivery-Invoice")
A46: C-044 | B46: JAA CO LTD | C46: MT2630-3713 | D46: Arzella Xitwija, Triq Gizi, Swieqi | F46: Commercial | G46: 46078 | H46: =COUNTIF('Orders & Payments'!$C$3:$C$200,$B46) | I46: =SUMIFS('Orders & Payments'!$N$3:$N$200,'Orders & Payments'!$C$3:$C$200,$B46,'Orders & Payments'!$G$3:$G$200,"Quotation") | J46: =SUMIFS('Orders & Payments'!$N$3:$N$200,'Orders & Payments'!$C$3:$C$200,$B46,'Orders & Payments'!$G$3:$G$200,"Invoice")+SUMIFS('Orders & Payments'!$N$3:$N$200,'Orders & Payments'!$C$3:$C$200,$B46,'Orders & Payments'!$G$3:$G$200,"Delivery-Invoice") | K46: =SUMIFS('Orders & Payments'!$O$3:$O$200,'Orders & Payments'!$C$3:$C$200,$B46) | L46: =SUMIFS('Orders & Payments'!$P$3:$P$200,'Orders & Payments'!$C$3:$C$200,$B46,'Orders & Payments'!$G$3:$G$200,"Invoice")+SUMIFS('Orders & Payments'!$P$3:$P$200,'Orders & Payments'!$C$3:$C$200,$B46,'Orders & Payments'!$G$3:$G$200,"Delivery-Invoice")
A47: C-045 | B47: Gordon Vella | C47: 16456105 | D47: Msida | F47: Private / TBC | G47: 46076 | H47: =COUNTIF('Orders & Payments'!$C$3:$C$200,$B47) | I47: =SUMIFS('Orders & Payments'!$N$3:$N$200,'Orders & Payments'!$C$3:$C$200,$B47,'Orders & Payments'!$G$3:$G$200,"Quotation") | J47: =SUMIFS('Orders & Payments'!$N$3:$N$200,'Orders & Payments'!$C$3:$C$200,$B47,'Orders & Payments'!$G$3:$G$200,"Invoice")+SUMIFS('Orders & Payments'!$N$3:$N$200,'Orders & Payments'!$C$3:$C$200,$B47,'Orders & Payments'!$G$3:$G$200,"Delivery-Invoice") | K47: =SUMIFS('Orders & Payments'!$O$3:$O$200,'Orders & Payments'!$C$3:$C$200,$B47) | L47: =SUMIFS('Orders & Payments'!$P$3:$P$200,'Orders & Payments'!$C$3:$C$200,$B47,'Orders & Payments'!$G$3:$G$200,"Invoice")+SUMIFS('Orders & Payments'!$P$3:$P$200,'Orders & Payments'!$C$3:$C$200,$B47,'Orders & Payments'!$G$3:$G$200,"Delivery-Invoice")
A48: C-046 | B48: BJORN | D48: Zabbar | F48: Private / TBC | G48: 46079 | H48: =COUNTIF('Orders & Payments'!$C$3:$C$200,$B48) | I48: =SUMIFS('Orders & Payments'!$N$3:$N$200,'Orders & Payments'!$C$3:$C$200,$B48,'Orders & Payments'!$G$3:$G$200,"Quotation") | J48: =SUMIFS('Orders & Payments'!$N$3:$N$200,'Orders & Payments'!$C$3:$C$200,$B48,'Orders & Payments'!$G$3:$G$200,"Invoice")+SUMIFS('Orders & Payments'!$N$3:$N$200,'Orders & Payments'!$C$3:$C$200,$B48,'Orders & Payments'!$G$3:$G$200,"Delivery-Invoice") | K48: =SUMIFS('Orders & Payments'!$O$3:$O$200,'Orders & Payments'!$C$3:$C$200,$B48) | L48: =SUMIFS('Orders & Payments'!$P$3:$P$200,'Orders & Payments'!$C$3:$C$200,$B48,'Orders & Payments'!$G$3:$G$200,"Invoice")+SUMIFS('Orders & Payments'!$P$3:$P$200,'Orders & Payments'!$C$3:$C$200,$B48,'Orders & Payments'!$G$3:$G$200,"Delivery-Invoice")
A49: C-047 | B49: MARSA | D49: Marsa | F49: Private / TBC | G49: 46074 | H49: =COUNTIF('Orders & Payments'!$C$3:$C$200,$B49) | I49: =SUMIFS('Orders & Payments'!$N$3:$N$200,'Orders & Payments'!$C$3:$C$200,$B49,'Orders & Payments'!$G$3:$G$200,"Quotation") | J49: =SUMIFS('Orders & Payments'!$N$3:$N$200,'Orders & Payments'!$C$3:$C$200,$B49,'Orders & Payments'!$G$3:$G$200,"Invoice")+SUMIFS('Orders & Payments'!$N$3:$N$200,'Orders & Payments'!$C$3:$C$200,$B49,'Orders & Payments'!$G$3:$G$200,"Delivery-Invoice") | K49: =SUMIFS('Orders & Payments'!$O$3:$O$200,'Orders & Payments'!$C$3:$C$200,$B49) | L49: =SUMIFS('Orders & Payments'!$P$3:$P$200,'Orders & Payments'!$C$3:$C$200,$B49,'Orders & Payments'!$G$3:$G$200,"Invoice")+SUMIFS('Orders & Payments'!$P$3:$P$200,'Orders & Payments'!$C$3:$C$200,$B49,'Orders & Payments'!$G$3:$G$200,"Delivery-Invoice")
A50: C-048 | B50: MOSTA | D50: Mosta | F50: Private / TBC | G50: 46083 | H50: =COUNTIF('Orders & Payments'!$C$3:$C$200,$B50) | I50: =SUMIFS('Orders & Payments'!$N$3:$N$200,'Orders & Payments'!$C$3:$C$200,$B50,'Orders & Payments'!$G$3:$G$200,"Quotation") | J50: =SUMIFS('Orders & Payments'!$N$3:$N$200,'Orders & Payments'!$C$3:$C$200,$B50,'Orders & Payments'!$G$3:$G$200,"Invoice")+SUMIFS('Orders & Payments'!$N$3:$N$200,'Orders & Payments'!$C$3:$C$200,$B50,'Orders & Payments'!$G$3:$G$200,"Delivery-Invoice") | K50: =SUMIFS('Orders & Payments'!$O$3:$O$200,'Orders & Payments'!$C$3:$C$200,$B50) | L50: =SUMIFS('Orders & Payments'!$P$3:$P$200,'Orders & Payments'!$C$3:$C$200,$B50,'Orders & Payments'!$G$3:$G$200,"Invoice")+SUMIFS('Orders & Payments'!$P$3:$P$200,'Orders & Payments'!$C$3:$C$200,$B50,'Orders & Payments'!$G$3:$G$200,"Delivery-Invoice") | M50: Supply & install Travertine Beige Atone (Mosta) — Inv 1000304 (supply) + Inv 1000305 (install). Client name not confirmed.
A51: C-049 | B51: Stefan Gajic | D51: Sliema | F51: Private / TBC | G51: 46087 | H51: =COUNTIF('Orders & Payments'!$C$3:$C$200,$B51) -> 0 | I51: =SUMIFS('Orders & Payments'!$N$3:$N$200,'Orders & Payments'!$C$3:$C$200,$B51,'Orders & Payments'!$G$3:$G$200,"Quotation") -> 0 | J51: =SUMIFS('Orders & Payments'!$N$3:$N$200,'Orders & Payments'!$C$3:$C$200,$B51,'Orders & Payments'!$G$3:$G$200,"Invoice")+SUMIFS('Orders & Payments'!$N$3:$N$200,'Orders & Payments'!$C$3:$C$200,$B51,'Orders & Payments'!$G$3:$G$200,"Delivery-Invoice") -> 0 | K51: =SUMIFS('Orders & Payments'!$O$3:$O$200,'Orders & Payments'!$C$3:$C$200,$B51) -> 0 | L51: =SUMIFS('Orders & Payments'!$P$3:$P$200,'Orders & Payments'!$C$3:$C$200,$B51,'Orders & Payments'!$G$3:$G$200,"Invoice")+SUMIFS('Orders & Payments'!$P$3:$P$200,'Orders & Payments'!$C$3:$C$200,$B51,'Orders & Payments'!$G$3:$G$200,"Delivery-Invoice") -> 0
A52: C-050 | B52: Target Developments Ltd | D52: Isabella Court, Flt Triq il-Mejjiesa, Manikata MLH 5134 | F52: Developer / Contractor | G52: 45901 | H52: =COUNTIF('Orders & Payments'!$C$3:$C$200,$B52) -> 0 | I52: =SUMIFS('Orders & Payments'!$N$3:$N$200,'Orders & Payments'!$C$3:$C$200,$B52,'Orders & Payments'!$G$3:$G$200,"Quotation") -> 0 | J52: =SUMIFS('Orders & Payments'!$N$3:$N$200,'Orders & Payments'!$C$3:$C$200,$B52,'Orders & Payments'!$G$3:$G$200,"Invoice")+SUMIFS('Orders & Payments'!$N$3:$N$200,'Orders & Payments'!$C$3:$C$200,$B52,'Orders & Payments'!$G$3:$G$200,"Delivery-Invoice") -> 0 | K52: =SUMIFS('Orders & Payments'!$O$3:$O$200,'Orders & Payments'!$C$3:$C$200,$B52) -> 0 | L52: =SUMIFS('Orders & Payments'!$P$3:$P$200,'Orders & Payments'!$C$3:$C$200,$B52,'Orders & Payments'!$G$3:$G$200,"Invoice")+SUMIFS('Orders & Payments'!$P$3:$P$200,'Orders & Payments'!$C$3:$C$200,$B52,'Orders & Payments'!$G$3:$G$200,"Delivery-Invoice") -> 0
A53: C-051 | B53: ST Projects Ltd | D53: 143 The Strand, Gzira | F53: Developer / Contractor | G53: 46090 | H53: =COUNTIF('Orders & Payments'!$C$3:$C$200,$B53) -> 0 | I53: =SUMIFS('Orders & Payments'!$N$3:$N$200,'Orders & Payments'!$C$3:$C$200,$B53,'Orders & Payments'!$G$3:$G$200,"Quotation") -> 0 | J53: =SUMIFS('Orders & Payments'!$N$3:$N$200,'Orders & Payments'!$C$3:$C$200,$B53,'Orders & Payments'!$G$3:$G$200,"Invoice")+SUMIFS('Orders & Payments'!$N$3:$N$200,'Orders & Payments'!$C$3:$C$200,$B53,'Orders & Payments'!$G$3:$G$200,"Delivery-Invoice") -> 0 | K53: =SUMIFS('Orders & Payments'!$O$3:$O$200,'Orders & Payments'!$C$3:$C$200,$B53) -> 0 | L53: =SUMIFS('Orders & Payments'!$P$3:$P$200,'Orders & Payments'!$C$3:$C$200,$B53,'Orders & Payments'!$G$3:$G$200,"Invoice")+SUMIFS('Orders & Payments'!$P$3:$P$200,'Orders & Payments'!$C$3:$C$200,$B53,'Orders & Payments'!$G$3:$G$200,"Delivery-Invoice") -> 0
H55: TOTALS → | I55: =SUM(I3:I54) -> 286888.31 | J55: =SUM(J3:J54) -> 139259.89 | K55: =SUM(K3:K54) -> 12372.58 | L55: =SUM(L3:L54) -> 126887.31

Sheet Measurement Pipeline
A1: MEASUREMENT → QUOTE → DEPOSIT → START
A2: Ref | B2: Date Logged | C2: Client / Site | D2: Contact | E2: Location | F2: Work Required | G2: Stage | H2: Measure Date | I2: Quote No. | J2: Quote Value | K2: Deposit Req. | L2: Deposit Paid? | M2: Lead Time (days) | N2: Target Start | O2: Notes | Q2: Default deposit % | R2: 0.3
A3: L-001 | B3: 45868 | C3: Qrendi (site) | E3: Qrendi | F3: Supply of marble slabs (limestone / travertine) | G3: Quote Sent — Awaiting Confirmation | I3: 229 | J3: 1910.42 | K3: =ROUND(J3*$R$2,2) -> 573.13 | L3: No | O3: Confirm client identity & VAT.
A4: L-002 | B4: 45917 | C4: Marsa – Hand-Crafted Job | E4: Marsa | F4: Hand-crafted marble designs, bullnose + polish | G4: Quote Sent — Awaiting Confirmation | I4: 239 | J4: 4448.6 | K4: =ROUND(J4*$R$2,2) -> 1334.58 | L4: No | O4: Doc labelled "MARSA".
A5: L-003 | B5: 45931 | C5: ROGER SATARIANO & SON LTD | E5: Mriehel | F5: Lava Black stairs & façade (31.6 sqm) | G5: Quote Sent — Awaiting Confirmation | I5: 243 | J5: 5109.4 | K5: =ROUND(J5*$R$2,2) -> 1532.82 | L5: No | O5: Linked to delivered extras (MD-016).
A6: L-004 | B6: 45959 | C6: ICI LIMITED | E6: Villa Fiorini | F6: Remove & replace marble sills | G6: Quote Sent — Awaiting Confirmation | I6: 259 | J6: 566.4 | K6: =ROUND(J6*$R$2,2) -> 169.92 | L6: No | O6: Existing client (ICI Ltd).
A7: L-005 | B7: 45959 | C7: Jhon Soler | E7: 15 Howard St, Sliema | F7: Supply & install 7 lifts cladding | G7: Quote Sent — Awaiting Confirmation | I7: 258 | J7: 2737.6 | K7: =ROUND(J7*$R$2,2) -> 821.28 | L7: No | O7: Per-floor delivery included.
A8: L-006 | B8: 45625 | C8: Luqa New Airport | E8: Luqa Airport | F8: Biege lime stone supply & install | G8: Quote Sent — Awaiting Confirmation | I8: 175 | J8: 7791.92 | K8: =ROUND(J8*$R$2,2) -> 2337.58 | L8: No | O8: Old quote — confirm if still open.
A9: L-007 | B9: 45976 | C9: Dario | E9: Marsa | F9: Supply of kitchen top — Quartz Gold | G9: Quote Sent — Awaiting Confirmation | I9: 264 | J9: 4012 | K9: =ROUND(J9*$R$2,2) -> 1203.6 | L9: No | O9: OPTION A (vs Q265 Calacatta). Client picks ONE.
A10: L-008 | B10: 45976 | C10: Dario | E10: Marsa | F10: Supply of kitchen top — Quartz Calacatta Gold | G10: Quote Sent — Awaiting Confirmation | I10: 265 | J10: 3569.5 | K10: =ROUND(J10*$R$2,2) -> 1070.85 | L10: No | O10: OPTION B (vs Q264 Quartz Gold). Client picks ONE.
A11: L-009 | B11: 45992 | C11: ROGER SATARIANO & SON LTD | E11: Pool & BBQ area | F11: Supply & install travertine — pool & barbeque area | G11: Quote Sent — Awaiting Confirmation | I11: 267 | J11: 4460.4 | K11: =ROUND(J11*$R$2,2) -> 1338.12 | L11: No | O11: Existing client. Separate from Mriehel & Ta Xbiex jobs.
A12: L-010 | B12: 45996 | C12: WE MALTA LTD | E12: Attard | F12: Supply & install Biege stone — stairs & skirting (Attard) | G12: Confirmed — Deposit Paid | I12: 272 | J12: 10612.92 | K12: =ROUND(J12*$R$2,2) -> 3183.88 | L12: Yes | O12: WON — invoiced as Delivery-Invoice 1000294 (see Orders MD-030). 40% deposit per doc.
A13: L-011 | B13: 45996 | C13: Purchase Order 1 (MARSA) | E13: Marsa | F13: Supply & install Crema Galala — stairs, landing & entrance (65.6 sqm) | G13: Quote Sent — Awaiting Confirmation | I13: 271 | J13: 8184.24 | K13: =ROUND(J13*$R$2,2) -> 2455.27 | L13: No | O13: Client labelled "PURCHASE ORDER 1" — identify.
A14: L-012 | B14: 45996 | C14: WE MALTA LTD | E14: Birkirkara | F14: Supply & install Biege stone — internal/external stairs & skirting (Birkirkara) | G14: Confirmed — Deposit Paid | I14: 273 | J14: 10105.99 | K14: =ROUND(J14*$R$2,2) -> 3031.8 | L14: Yes | O14: WON — invoiced as Delivery-Invoice 1000295 (see Orders MD-032). 40% deposit per doc.
... A32: L-030 | B32: 46057 | C32: Purchase Order 1 (MARSA) | E32: Marsa | F32: Supply & install Prestige Grey & Bianco Carrera staircases + sills | G32: Quote Sent — Awaiting Confirmation | I32: 300 | J32: 42441.06 | K32: =ROUND(J32*$R$2,2) -> 12732.32 | L32: No | O32: Client "PURCHASE ORDER 1" — identify. Largest open quote.
A33: L-031 | B33: 46060 | C33: Purchase Order 1 (MARSA) | E33: Marsa | F33: Supply & install Calacatta Viola sink & backsplash | G33: Quote Sent — Awaiting Confirmation | I33: 301 | J33: 4017.9 | K33: =IF(J33="","",ROUND(J33*$R$2,2)) -> 1205.37 | L33: No | O33: Identify client. Install €200–300.
A34: L-032 | B34: 46060 | C34: ICI LIMITED | E34: Attard | F34: Supply of Travertine crosscut sills & stairs | G34: Quote Sent — Awaiting Confirmation | I34: 302 | J34: 4285.35 | K34: =IF(J34="","",ROUND(J34*$R$2,2)) -> 1285.61 | L34: No | O34: VAT MT17813220. MEASURED — cut list. F1 sills: 152.5×35, 4.55×21, 1.05×21 ×2, 1.115×26, 79.5×12, 1.09×26, 62×12, 98×26, 2.42×21, 1.12×21, 1.10×21. F2 sills: 1.51×26, 4.295×21, 1.02×21 ×2, 1.135×26, 80×12, 1.09×26, 99.5×26, 62×12, 1.09×26, 2.03×21, 1.01×21 ×2. F3 sills: 150.5×26, 4.29×21, 1.02×21 ×2, 1.15×26, 89×12, 1.09×26, 1.10×26, 62×12, 99.5×12, 2.03×21, 1.02×21 ×2. Penthouse: 3.955×27, 48.5×27, 6.75×27, 4.28×27, 49×27, 1.15×26, 1.10×26, 60×12, 80×12, 4.30×27, 3.75×27 ×2, 1.30×27, 1.51×21. Stairs: 94×1.50 ×4, 1.50×1.10 ×8, 1.15×2.20 ×4. Entrance: 1.15×2.20, 94×50 ×6, 2.10×3.50, 3.10×1.50. Outdoor: 2.70×1.50. (m unless cm)
A35: L-033 | B35: 46060 | C35: VGP PROPERTY INVESTMENT COMPANY LIMITED | E35: Floriana | F35: Supply & install Bianco Carrera sills | G35: Invoiced — Delivery-Invoice 1000290 | I35: 303 | J35: 687.35 | K35: =IF(J35="","",ROUND(J35*$R$2,2)) -> 206.21 | L35: No | O35: VAT 28035504. Bianco sills + install + delivery, Triq Antonio Aguis.
A36: L-034 | B36: 46060 | C36: VGP PROPERTY INVESTMENT COMPANY LIMITED | E36: Floriana | F36: Supply & install sills & stairs, F-1 to roof | G36: Quote Sent — Awaiting Confirmation | I36: 304 | J36: 5422.75 | K36: =IF(J36="","",ROUND(J36*$R$2,2)) -> 1626.83 | L36: No | O36: VAT 28035504. MEASURED — cut list (F-1 to roof). F-1 sills: 1.07×27, 1.10×27, 90×42, 91×41, 2.70×20 ×2, 70×20 ×2; F-1 stairs: 2.50×1.11, 15×1.11 ×6. F-2 sills: 4.53×25, 4.53×21, 91×36, 91×35.5, 91×35.4, 3.50×26, 4.40×22, 92×36, 91×36, 2.24×26 ×2, 1.42×26; F-2 stairs: 1.85×1.11, 1.11×15 ×5, 1.11×23 ×3. F-3 sills: 2.20×26 ×2, 90×40 ×2, 91×40 ×2, 92×40, 1.42×26; F-3 stairs: 1.33×1.11 ×2, 1.11×15 ×2, 1.11×40, 1.11×50. Roof sills: 75×26 ×2, 80.5×26, 12.55×26, 8.75×26, 2.90×18, 1.63×18, 2.00×26 ×2, 1.40×26. (m unless cm)
A37: L-035 | B37: 46055 | C37: Joesph Guzieppe Callus | E37: Mosta | F37: Supply & install Dino brushed stairs + sills | G37: Quote Sent — Awaiting Confirmation | I37: 292 | J37: 7149.62 | K37: =IF(J37="","",ROUND(J37*$R$2,2)) -> 2144.89 | L37: No | O37: No VAT on doc — confirm.
A38: L-036 | B38: 46065 | C38: Maria | E38: Mosta | F38: Supply & install Taj Mahal kitchen top + splashback + island | G38: Quote Sent — Awaiting Confirmation | I38: 305 | J38: 7398.6 | K38: =IF(J38="","",ROUND(J38*$R$2,2)) -> 2219.58 | L38: No | O38: VAT 26849627, Il-Maxtura, Mosta.
A39: L-037 | B39: 46065 | C39: Itiana | E39: Marsaskala | F39: Supply & install travertine, multi-floor | G39: Invoiced — Delivery-Invoice 1000296 | I39: 306 | J39: 9196.92 | K39: =IF(J39="","",ROUND(J39*$R$2,2)) -> 2759.08 | L39: No | O39: No VAT on doc — confirm.
A40: L-038 | B40: 46067 | C40: MSIDA | E40: Msida | F40: Supply & Install Bianco Carrara Sills (Roof Sills, Round Sills, Level 1+2+3+4, Install) | G40: Invoiced — Delivery-Invoice 1000303 (partial, deposit paid) | I40: 309 | J40: 17941.43 | K40: =IF(J40="","",ROUND(J40*$R$2,2)) | L40: No | O40: Open quote — add to Measurement Pipeline
A41: L-039 | B41: 46067 | C41: GUDJA | E41: Gudja | F41: Supply & Install Staircase Beige (Stairs & Skirting) | G41: Quote Sent — Awaiting Confirmation | I41: 310 | J41: 11016.48 | K41: =IF(J41="","",ROUND(J41*$R$2,2)) | L41: No | O41: Open quote — add to Measurement Pipeline
A42: L-040 | B42: 46074 | C42: Blane | E42: Santa Lucia | F42: Supply of Crema Marfil Sills + Delivery | G42: Quote Sent — Awaiting Confirmation | I42: 317 | J42: 551.65 | K42: =IF(J42="","",ROUND(J42*$R$2,2)) | L42: No | O42: Open quote — Santa Lucia
A43: L-041 | B43: 46074 | C43: MARSA | E43: Marsa | F43: Supply of Crema Galala Sills + Delivery | G43: Quote Sent — Awaiting Confirmation | I43: 318 | J43: 457.25 | K43: =IF(J43="","",ROUND(J43*$R$2,2)) | L43: No | O43: Client name not on document — confirm client name
A44: L-042 | B44: 46076 | C44: Gordon Vella | E44: Msida | F44: Supply of Light Travertine Sills (Sills, Stairs, Entrance) | G44: Quote Sent — Awaiting Confirmation | I44: 323 | J44: 24763.72 | K44: =IF(J44="","",ROUND(J44*$R$2,2)) | L44: No | O44: Open quote — add to Measurement Pipeline
... A46: L-044 | B46: 46079 | C46: BJORN | E46: Zabbar | F46: Supply & Install Quarzite & Crema Marfil Marble (back light included with installation) | G46: Quote Sent — Awaiting Confirmation | I46: 325 | J46: 7882.4 | K46: =IF(J46="","",ROUND(J46*$R$2,2)) | L46: No | O46: Open quote — back light included with installation; add to Measurement Pipeline
K47: =IF(J47="","",ROUND(J47*$R$2,2))
K48: =IF(J48="","",ROUND(J48*$R$2,2))
K49: =IF(J49="","",ROUND(J49*$R$2,2))
K50: =IF(J50="","",ROUND(J50*$R$2,2))
K51: =IF(J51="","",ROUND(J51*$R$2,2))
K52: =IF(J52="","",ROUND(J52*$R$2,2))
K53: =IF(J53="","",ROUND(J53*$R$2,2))
K54: =IF(J54="","",ROUND(J54*$R$2,2))
K55: =IF(J55="","",ROUND(J55*$R$2,2))
K56: =IF(J56="","",ROUND(J56*$R$2,2))
K57: =IF(J57="","",ROUND(J57*$R$2,2))
K58: =IF(J58="","",ROUND(J58*$R$2,2))
...

Sheet Cutting Log
A1: CUTTING LOG — what the machine cutter cut each day
A2: Date | B2: Cutter | C2: Order ID | D2: Client / Site | E2: Invoice / Quote | F2: Material | G2: Pieces / Sizes Cut | H2: Sqm Cut | I2: Lm Cut | J2: Chamfer Done? | K2: Chamfer By | L2: Status | M2: Notes
A3: 45966 | B3: Cutter (rename) | C3: MD-017 | D3: PROJECT TECHNIK LTD | E3: 1000255 | F3: Trista Grey | G3: 27 sqm slabs cut to size | H3: 27 | J3: Yes | K3: Chamfer (rename) | L3: Completed | M3: EXAMPLE — Trista Grey order delivered
A4: 45967 | B4: Cutter (rename) | C4: MD-019 | D4: Lee | E4: 1000256 | F4: Biege Travertine | G4: Sills: 90.5×26, 66×26, 91×26, 1m×26, 1m×25, 90×32, 84×10, 54×10, 88×21, 86×21 (11 pcs) | H4: 2.5 | J4: Yes | K4: Chamfer (rename) | L4: Ready for Delivery | M4: EXAMPLE — travertine sills
A5: 45974 | B5: Cutter (rename) | C5: MD-020 | D5: STEPHEN FARRUGIA | E5: 1000258 | F5: Marble | G5: Install pieces — Santa Venera | J5: Yes | K5: Chamfer (rename) | L5: In Progress | M5: EXAMPLE — supply & install balance

Sheet Daily Work Log
A1: DAILY WORK LOG — what every worker did today
A2: Date | B2: Worker | C2: Role | D2: Activity | E2: Order ID | F2: Client / Site | G2: Material | H2: Details (what they did) | I2: Qty (pcs) | J2: Sqm / Lm | K2: Hours | L2: Status | M2: Notes
A3: 45967 | B3: Cutter (rename) | C3: Machine Cutter | D3: Cutting | E3: MD-019 | F3: Lee | G3: Biege Travertine | H3: Cut 11 travertine sills to required sizes | I3: 11 | K3: 5 | L3: Completed | M3: EXAMPLE
A4: 45967 | B4: Chamfer (rename) | C4: Chamfer | D4: Chamfering | E4: MD-019 | F4: Lee | G4: Biege Travertine | H4: Chamfered / edged 11 sills | I4: 11 | K4: 3 | L4: Completed | M4: EXAMPLE
A5: 45967 | B5: Helper (rename) | C5: Helper | D5: Factory Help | E5: MD-019 | F5: Lee | H5: Moved slabs to cutter, cleaned, stacked finished pieces | K5: 6 | L5: Completed | M5: EXAMPLE
A6: 45967 | B6: Driver (rename) | C6: Driver | D6: Delivery | E6: MD-019 | F6: Lee (Marsa) | H6: Delivered finished sills to site + unloaded | K6: 2 | L6: Completed | M6: EXAMPLE
A7: 45967 | B7: Driver (rename) | C7: Driver | D7: Factory Help | H7: Helped load van, moved offcuts, tidied yard | K7: 3 | L7: Completed | M7: EXAMPLE
A8: 45966 | B8: Cutter (rename) | C8: Machine Cutter | D8: Cutting | E8: MD-017 | F8: PROJECT TECHNIK LTD | G8: Trista Grey | H8: Cut 27 sqm Trista Grey to size | J8: 27 | K8: 6 | L8: Completed | M8: EXAMPLE

Sheet Attendance
A1: WORKER ATTENDANCE — arrival times, factory & outside
A2: Date | B2: Worker | C2: Role | D2: Work Location | E2: Time In | F2: Time Out | G2: Hours | H2: Status | I2: Notes
A3: 45967 | B3: Cutter (rename) | C3: Machine Cutter | D3: Factory | E3: 0.29166667 | F3: 0.6875 | G3: =IF(OR(E3="",F3=""),"",(F3-E3)*24) -> 9.5 | H3: Present | I3: —
A4: 45967 | B4: Chamfer (rename) | C4: Chamfer | D4: Factory | E4: 0.30208333 | F4: 0.6875 | G4: =IF(OR(E4="",F4=""),"",(F4-E4)*24) -> 9.25 | H4: Late | I4: In 15 min late
A5: 45967 | B5: Helper (rename) | C5: Helper | D5: Factory | E5: 0.29166667 | F5: 0.66666667 | G5: =IF(OR(E5="",F5=""),"",(F5-E5)*24) -> 9 | H5: Present | I5: —
A6: 45967 | B6: Driver (rename) | C6: Driver | D6: Outside / Site | E6: 0.28125 | F6: 0.70833333 | G6: =IF(OR(E6="",F6=""),"",(F6-E6)*24) -> 10.25 | H6: Present | I6: Deliveries Marsa + Qormi
A7: 45967 | B7: Installer (rename) | C7: Installer | D7: Outside / Site | E7: 0.3125 | F7: 0.6875 | G7: =IF(OR(E7="",F7=""),"",(F7-E7)*24) -> 9 | H7: Present | I7: On site — Zebbug flats
G8: =IF(OR(E8="",F8=""),"",(F8-E8)*24)
G9: =IF(OR(E9="",F9=""),"",(F9-E9)*24)
G10: =IF(OR(E10="",F10=""),"",(F10-E10)*24)
G11: =IF(OR(E11="",F11=""),"",(F11-E11)*24)
G12: =IF(OR(E12="",F12=""),"",(F12-E12)*24)
G13: =IF(OR(E13="",F13=""),"",(F13-E13)*24)
G14: =IF(OR(E14="",F14=""),"",(F14-E14)*24)
G15: =IF(OR(E15="",F15=""),"",(F15-E15)*24)
G16: =IF(OR(E16="",F16=""),"",(F16-E16)*24)
G17: =IF(OR(E17="",F17=""),"",(F17-E17)*24)
G18: =IF(OR(E18="",F18=""),"",(F18-E18)*24)
G19: =IF(OR(E19="",F19=""),"",(F19-E19)*24)
... G400: =IF(OR(E400="",F400=""),"",(F400-E400)*24)

Sheet Workers
A1: WORKERS — team roster
A2: Worker ID | B2: Name | C2: Role | D2: Base | E2: Phone | F2: Rate | G2: Rate Type | H2: Start Date | I2: Status | J2: Notes
A3: W-001 | B3: Cutter (rename) | C3: Machine Cutter | D3: Factory | G3: Daily | I3: Active | J3: Operates the cutting machine.
A4: W-002 | B4: Chamfer (rename) | C4: Chamfer / Edging | D4: Factory | G4: Daily | I4: Active | J4: Chamfering / bullnose / edge finishing.
A5: W-003 | B5: Helper (rename) | C5: Helper | D5: Factory | G5: Daily | I5: Active | J5: Moves slabs, assists cutter, yard work.
A6: W-004 | B6: Driver (rename) | C6: Driver / Delivery | D6: Both | G6: Daily | I6: Active | J6: Deliveries + helps in factory between runs.
A7: W-005 | B7: Installer (rename) | C7: Installer | D7: Outside / Site | G7: Daily | I7: Active | J7: Fits sills, stairs, cladding on site.
A8: W-006 | B8: Mason (rename) | C8: Mason / Fixer | D8: Outside / Site | G8: Daily | I8: Active | J8: Leveling, fixing, finishing on site.

Sheet Guide
A1: HOW TO USE THIS WORKBOOK
B4: TAB | C4: WHAT IT IS FOR
B5: Dashboard | C5: Live snapshot — money invoiced, money received, money still owed, and value of quotes not yet confirmed. Updates by itself.
